Workbook

Sheet Assumptions
A1: scoup.ai financial model: Assumptions (all inputs; blue = editable input)
A2: Pre-product, pre-revenue, no customers, synthetic data only. Every figure is a plan input or its arithmetic consequence, not a forecast. $K unless stated. Year 1 = first 12 months after seed close.
A3: Input | B3: Value / Y1 | C3: Y2 / Bull | D3: Y3 / Bear | E3: Y4 / Live | F3: Y5 | G3: Y6 | H3: Y7 | I3: Status | J3: Source / reasoning
A4: Scenario control
A5: Active scenario (1 = Base, 2 = Bull, 3 = Bear) | B5: 1 | I5: CONTROL | J5: Drives every main tab. The Scenarios tab computes all three side by side regardless.
A6: Year index | B6: 1 | C6: 2 | D6: 3 | E6: 4 | F6: 5 | G6: 6 | H6: 7 | I6: STRUCTURAL | J6: Used by formulas that depend on the year number.
A7: Global inputs (same in every scenario)
A8: Compensation inflation per year | B8: 0.04 | I8: ASSUMED | J8: Planning assumption carried from the investor-pack workbook (grade C).
A9: NOK per USD | B9: 9.3817 | I9: SOURCED | J9: Norges Bank, USD/NOK monthly average Sep 2026 = 9.3817, https://data.norges-bank.no/api/data/EXR/M.USD.NOK.SP, accessed 2026-10-17. Replaces 10.5 in the prior workbook.
A10: Norway loading on gross salary (employer tax + pension + other) | B10: 1.22 | I10: ASSUMED | J10: Employer tax zone I 14.1% is SOURCED (Skatteetaten, https://www.skatteetaten.no/satser/arbeidsgiveravgift/, accessed 2026-10-17); the remaining ~8 points (mandatory pension, insurance) are assumed.
A11: US benefits share of total compensation | B11: 0.3 | I11: SOURCED | J11: BLS Employer Costs for Employee Compensation, June 2026: benefits 30.0% of private-industry compensation, https://www.bls.gov/news.release/ecec.nr0.htm, accessed 2026-10-17. Loaded cost = wage / (1 - 0.30).
A12: Norwegian corporate income tax rate | B12: 0.22 | I12: SOURCED | J12: 22% (DLA Piper Global Expansion Tax, Norway, https://intelligence.dlapiper.com/global-expansion-tax/?c=NO, accessed 2026-10-17). Unlimited loss carry-forward assumed; confirm with counsel.
A13: Days sales outstanding | B13: 60 | I13: ASSUMED | J13: Contingency fees are invoiced after the counterparty pays the customer; 60 days assumed. Unmeasured.
A14: Days payable outstanding (non-payroll costs) | B14: 30 | I14: ASSUMED | J14: Standard 30-day vendor terms assumed.
A15: Equipment capex per net new hire ($K) | B15: 3 | I15: ASSUMED | J15: Laptop and peripherals. Software development is expensed, not capitalised.
A16: Depreciation life (years) | B16: 3 | I16: ASSUMED | J16: Straight line.
A17: Interest earned on cash | B17: 0 | I17: ASSUMED | J17: Set to zero for conservatism.
A18: Opening cash at seed close, before seed ($K) | B18: 0 | I18: ASSUMED | J18: UNKNOWN; owner to confirm founder-funded cash and share capital (NOK 30,000 minimum for an AS).
A19: Series A ARR milestone ($K) | B19: 2500 | I19: ASSUMED | J19: Planning target. Reference: median ARR at Series A $2.8M in 2025 (Carta, ARR at Series A, https://carta.com/data/newsletter-arr-at-series-a/, figure confirmed via search result 2026-10-17; direct fetch returned HTTP 403).
... A33: Pessimistic CAC: paid-media cost per small-company customer ($K) | B33: 31 | I33: SOURCED | J33: Metadata.io, 2026 B2B Paid Media Benchmark Report (2025 data, 153 advertisers): small-company customer cost $31k, https://metadata.io/md/benchmark-report-2026.md, accessed 2026-10-17. Media cost only; excludes sales labour. LinkedIn cost per customer $58,572 (same source, reported by digital-marketing, not re-verified by finance).
A34: Revenue per account build, base path ($K per account per year) | B34: Y1 | C34: Y2 | D34: Y3 | E34: Y4 | F34: Y5 | G34: Y6 | H34: Y7
A35: Platform fee | B35: 0 | C35: 6 | D35: 10 | E35: 13 | F35: 15 | G35: 16 | H35: 17 | I35: ASSUMED | J35: Investor-pack workbook (grade C). Hybrid fee starts in year 2. No competitor publishes pricing (market-researcher research/01-competitors.md, 2026-10-17), so there is no market check.
A36: Amount recovered for the customer | B36: 52 | C36: 70 | D36: 85 | E36: 95 | F36: 105 | G36: 110 | H36: 115 | I36: ASSUMED | J36: Year 1 $52K = business-case base for a mid-size importer-shipper (D&D $36K + fuel surcharge $16K), built on FMC and EIA/ATRI figures; grows as modules are added. Not measured on any customer data.
A37: Recovery share (contingency %) | B37: 0.25 | C37: 0.17 | D37: 0.14 | E37: 0.12 | F37: 0.12 | G37: 0.12 | H37: 0.12 | I37: ASSUMED | J37: 25% pilot contingency, falling once the platform fee starts. No freight competitor publishes a contingency rate (market-researcher research/01-competitors.md, 2026-10-17). Only public reference: Refund Retriever (parcel audit) 40-50%, https://www.refundretriever.com/pricing, accessed 2026-10-17.
A38: Segments: shippers and SME importers are the core; carriers are a later, partner-led segment
A39: Shipper share of new shipper + importer accounts | B39: 0.5 | I39: ASSUMED | J39: Owner decision 2026-10-17: shipper- and importer-first. 50/50 split assumed; SME importers are counted (234,023, US Census) but mid-market shippers are not yet.
A40: Shipper amount recovered vs importer path | B40: 0.77 | I40: ASSUMED | J40: A domestic mid-market shipper has no ocean D&D. Business-case year-1 example: fuel-surcharge recovery $16K (business case, EIA-based) + accessorial and detention invoice audit $24K (assumed) = $40K vs $52K for an importer = 0.77.
A41: Carrier: amount recovered per carrier ($K/yr) | B41: 39.475 | C41: 39.475 | D41: 39.475 | E41: 39.475 | F41: 39.475 | G41: 39.475 | H41: 39.475 | I41: ASSUMED | J41: market-researcher research/02 and 05 (2026-10-17): $471.60 fee per power unit x 16.7 units = $7,895 per carrier at a 20% fee, so recovered = $7,895 / 20% = $39.5K. Built on assumed inputs (400 stops per truck, $100 per detained stop, 30% winnable); ATRI 39.3% detention rate sourced.
A42: Carrier: contingency share (no platform fee) | B42: 0.2 | I42: ASSUMED | J42: Fee used in the research carrier model and in gtm.md.
A43: Partner commission on carrier revenue (factoring / ELD channel) | B43: 0.2 | I43: ASSUMED | J43: Carriers come through a channel partner, not direct sales; commission booked in the Sales department.
A44: Scenario inputs (scalars) | B44: Base | C44: Bull | D44: Bear | E44: Live
A45: Annual logo churn | B45: 0.2 | C45: 0.15 | D45: 0.3 | E45: =CHOOSE($B$5,B45,C45,D45) | I45: ASSUMED | J45: Share of start-of-year accounts lost in the year. Benchmarkit median GRR 88% implies ~12% revenue churn for SaaS; a contingency service is easy to switch off, so 20% base.
A46: Revenue per account vs base path | B46: 1 | C46: 1.15 | D46: 0.8 | E46: =CHOOSE($B$5,B46,C46,D46) | I46: ASSUMED | J46: Bull: larger recoveries and early platform-fee adoption. Bear: recoveries 20% lower.
A47: Headcount and spend scale vs base plan | B47: 1 | C47: 1.1 | D47: 0.85 | E47: =CHOOSE($B$5,B47,C47,D47) | I47: ASSUMED | J47: Applied to every role except the founder, and to other operating costs from year 2.
A48: Hold headcount and spend at prior-year level from year (0 = never) | B48: 0 | C48: 0 | D48: 3 | E48: =CHOOSE($B$5,B48,C48,D48) | I48: ASSUMED | J48: Bear cost response: if the tranche-2 milestone is missed, hold at year-2 levels (investor-pack financial plan section 4 describes this but the workbook did not model it).
A49: Number of years the hold lasts | B49: 0 | C49: 0 | D49: 2 | E49: =CHOOSE($B$5,B49,C49,D49) | I49: ASSUMED | J49: Bear: years 3 and 4 held at year-2 levels, then the scaled plan resumes. A permanent hold would leave 2 claims analysts serving 235 accounts, which is not credible.
A50: Variable cost of revenue (% of revenue) | B50: 0.08 | C50: 0.07 | D50: 0.1 | E50: =CHOOSE($B$5,B50,C50,D50) | I50: ASSUMED | J50: New input: LLM inference, OCR and per-container event data. Unmeasured; replaces the gross-margin-% input of the prior workbook.
A51: Scenario inputs (by year): new shipper + importer accounts won, and carrier accounts | B51: Y1 | C51: Y2 | D51: Y3 | E51: Y4 | F51: Y5 | G51: Y6 | H51: Y7
A52: New shipper + importer accounts won - Base | B52: 6 | C52: 30 | D52: 75 | E52: 120 | F52: 165 | G52: 200 | H52: 235 | I52: ASSUMED | J52: Plan input from the investor-pack workbook (grade C). No pipeline exists yet.
A53: New shipper + importer accounts won - Bull | B53: 8 | C53: 40 | D53: 100 | E53: 160 | F53: 215 | G53: 260 | H53: 300 | I53: ASSUMED | J53: Plan input from the investor-pack workbook (grade C). No pipeline exists yet.
...

Sheet Revenue
A1: Revenue build (active scenario)
A2: Accounts x revenue per account. Revenue per account = (platform fee + amount recovered x recovery share) x scenario multiplier.
A3: $K unless stated | B3: ="Y"&Assumptions!$B$6 | C3: ="Y"&Assumptions!$C$6 | D3: ="Y"&Assumptions!$D$6 | E3: ="Y"&Assumptions!$E$6 | F3: ="Y"&Assumptions!$F$6 | G3: ="Y"&Assumptions!$G$6 | H3: ="Y"&Assumptions!$H$6
A4: Accounts and revenue by segment ($K)
A5: Shippers (mid-market): new accounts | B5: =ROUND(Assumptions!$B$55*Assumptions!$B$39,0) | C5: =ROUND(Assumptions!$C$55*Assumptions!$B$39,0) | D5: =ROUND(Assumptions!$D$55*Assumptions!$B$39,0) | E5: =ROUND(Assumptions!$E$55*Assumptions!$B$39,0) | F5: =ROUND(Assumptions!$F$55*Assumptions!$B$39,0) | G5: =ROUND(Assumptions!$G$55*Assumptions!$B$39,0) | H5: =ROUND(Assumptions!$H$55*Assumptions!$B$39,0)
A6: Shippers (mid-market): accounts lost = ROUND(prior year-end x churn) | B6: =0 | C6: =ROUND(B7*Assumptions!$E$45,0) | D6: =ROUND(C7*Assumptions!$E$45,0) | E6: =ROUND(D7*Assumptions!$E$45,0) | F6: =ROUND(E7*Assumptions!$E$45,0) | G6: =ROUND(F7*Assumptions!$E$45,0) | H6: =ROUND(G7*Assumptions!$E$45,0)
A7: Shippers (mid-market): accounts at year end | B7: =B5 | C7: =B7-C6+C5 | D7: =C7-D6+D5 | E7: =D7-E6+E5 | F7: =E7-F6+F5 | G7: =F7-G6+G5 | H7: =G7-H6+H5
A8: Shippers (mid-market): average accounts | B8: =B7/2 | C8: =(B7+C7)/2 | D8: =(C7+D7)/2 | E8: =(D7+E7)/2 | F8: =(E7+F7)/2 | G8: =(F7+G7)/2 | H8: =(G7+H7)/2
A9: Shippers (mid-market): revenue per account ($K) | B9: =(Assumptions!$B$35+Assumptions!$B$36*Assumptions!$B$40*Assumptions!$B$37)*Assumptions!$E$46 | C9: =(Assumptions!$C$35+Assumptions!$C$36*Assumptions!$B$40*Assumptions!$C$37)*Assumptions!$E$46 | D9: =(Assumptions!$D$35+Assumptions!$D$36*Assumptions!$B$40*Assumptions!$D$37)*Assumptions!$E$46 | E9: =(Assumptions!$E$35+Assumptions!$E$36*Assumptions!$B$40*Assumptions!$E$37)*Assumptions!$E$46 | F9: =(Assumptions!$F$35+Assumptions!$F$36*Assumptions!$B$40*Assumptions!$F$37)*Assumptions!$E$46 | G9: =(Assumptions!$G$35+Assumptions!$G$36*Assumptions!$B$40*Assumptions!$G$37)*Assumptions!$E$46 | H9: =(Assumptions!$H$35+Assumptions!$H$36*Assumptions!$B$40*Assumptions!$H$37)*Assumptions!$E$46
A10: Shippers (mid-market): revenue | B10: =B8*B9 | C10: =C8*C9 | D10: =D8*D9 | E10: =E8*E9 | F10: =F8*F9 | G10: =G8*G9 | H10: =H8*H9
A11: Shippers (mid-market): ARR at year end | B11: =B7*B9 | C11: =C7*C9 | D11: =D7*D9 | E11: =E7*E9 | F11: =F7*F9 | G11: =G7*G9 | H11: =H7*H9
A12: SME importers: new accounts | B12: =Assumptions!$B$55-ROUND(Assumptions!$B$55*Assumptions!$B$39,0) | C12: =Assumptions!$C$55-ROUND(Assumptions!$C$55*Assumptions!$B$39,0) | D12: =Assumptions!$D$55-ROUND(Assumptions!$D$55*Assumptions!$B$39,0) | E12: =Assumptions!$E$55-ROUND(Assumptions!$E$55*Assumptions!$B$39,0) | F12: =Assumptions!$F$55-ROUND(Assumptions!$F$55*Assumptions!$B$39,0) | G12: =Assumptions!$G$55-ROUND(Assumptions!$G$55*Assumptions!$B$39,0) | H12: =Assumptions!$H$55-ROUND(Assumptions!$H$55*Assumptions!$B$39,0)
A13: SME importers: accounts lost = ROUND(prior year-end x churn) | B13: =0 | C13: =ROUND(B14*Assumptions!$E$45,0) | D13: =ROUND(C14*Assumptions!$E$45,0) | E13: =ROUND(D14*Assumptions!$E$45,0) | F13: =ROUND(E14*Assumptions!$E$45,0) | G13: =ROUND(F14*Assumptions!$E$45,0) | H13: =ROUND(G14*Assumptions!$E$45,0)
A14: SME importers: accounts at year end | B14: =B12 | C14: =B14-C13+C12 | D14: =C14-D13+D12 | E14: =D14-E13+E12 | F14: =E14-F13+F12 | G14: =F14-G13+G12 | H14: =G14-H13+H12
A15: SME importers: average accounts | B15: =B14/2 | C15: =(B14+C14)/2 | D15: =(C14+D14)/2 | E15: =(D14+E14)/2 | F15: =(E14+F14)/2 | G15: =(F14+G14)/2 | H15: =(G14+H14)/2
A16: SME importers: revenue per account ($K) | B16: =(Assumptions!$B$35+Assumptions!$B$36*Assumptions!$B$37)*Assumptions!$E$46 | C16: =(Assumptions!$C$35+Assumptions!$C$36*Assumptions!$C$37)*Assumptions!$E$46 | D16: =(Assumptions!$D$35+Assumptions!$D$36*Assumptions!$D$37)*Assumptions!$E$46 | E16: =(Assumptions!$E$35+Assumptions!$E$36*Assumptions!$E$37)*Assumptions!$E$46 | F16: =(Assumptions!$F$35+Assumptions!$F$36*Assumptions!$F$37)*Assumptions!$E$46 | G16: =(Assumptions!$G$35+Assumptions!$G$36*Assumptions!$G$37)*Assumptions!$E$46 | H16: =(Assumptions!$H$35+Assumptions!$H$36*Assumptions!$H$37)*Assumptions!$E$46
A17: SME importers: revenue | B17: =B15*B16 | C17: =C15*C16 | D17: =D15*D16 | E17: =E15*E16 | F17: =F15*F16 | G17: =G15*G16 | H17: =H15*H16
A18: SME importers: ARR at year end | B18: =B14*B16 | C18: =C14*C16 | D18: =D14*D16 | E18: =E14*E16 | F18: =F14*F16 | G18: =G14*G16 | H18: =H14*H16
A19: Carriers (partner-led): new accounts | B19: =Assumptions!$B$59 | C19: =Assumptions!$C$59 | D19: =Assumptions!$D$59 | E19: =Assumptions!$E$59 | F19: =Assumptions!$F$59 | G19: =Assumptions!$G$59 | H19: =Assumptions!$H$59
A20: Carriers (partner-led): accounts lost = ROUND(prior year-end x churn) | B20: =0 | C20: =ROUND(B21*Assumptions!$E$45,0) | D20: =ROUND(C21*Assumptions!$E$45,0) | E20: =ROUND(D21*Assumptions!$E$45,0) | F20: =ROUND(E21*Assumptions!$E$45,0) | G20: =ROUND(F21*Assumptions!$E$45,0) | H20: =ROUND(G21*Assumptions!$E$45,0)
A21: Carriers (partner-led): accounts at year end | B21: =B19 | C21: =B21-C20+C19 | D21: =C21-D20+D19 | E21: =D21-E20+E19 | F21: =E21-F20+F19 | G21: =F21-G20+G19 | H21: =G21-H20+H19
A22: Carriers (partner-led): average accounts | B22: =B21/2 | C22: =(B21+C21)/2 | D22: =(C21+D21)/2 | E22: =(D21+E21)/2 | F22: =(E21+F21)/2 | G22: =(F21+G21)/2 | H22: =(G21+H21)/2
A23: Carriers (partner-led): revenue per account ($K) | B23: =Assumptions!$B$41*Assumptions!$B$42*Assumptions!$E$46 | C23: =Assumptions!$C$41*Assumptions!$B$42*Assumptions!$E$46 | D23: =Assumptions!$D$41*Assumptions!$B$42*Assumptions!$E$46 | E23: =Assumptions!$E$41*Assumptions!$B$42*Assumptions!$E$46 | F23: =Assumptions!$F$41*Assumptions!$B$42*Assumptions!$E$46 | G23: =Assumptions!$G$41*Assumptions!$B$42*Assumptions!$E$46 | H23: =Assumptions!$H$41*Assumptions!$B$42*Assumptions!$E$46
A24: Carriers (partner-led): revenue | B24: =B22*B23 | C24: =C22*C23 | D24: =D22*D23 | E24: =E22*E23 | F24: =F22*F23 | G24: =G22*G23 | H24: =H22*H23
A25: Carriers (partner-led): ARR at year end | B25: =B21*B23 | C25: =C21*C23 | D25: =D21*D23 | E25: =E21*E23 | F25: =F21*F23 | G25: =G21*G23 | H25: =H21*H23
A26: All segments: new accounts won | B26: =B5+B12+B19 | C26: =C5+C12+C19 | D26: =D5+D12+D19 | E26: =E5+E12+E19 | F26: =F5+F12+F19 | G26: =G5+G12+G19 | H26: =H5+H12+H19
A27: All segments: accounts lost | B27: =B6+B13+B20 | C27: =C6+C13+C20 | D27: =D6+D13+D20 | E27: =E6+E13+E20 | F27: =F6+F13+F20 | G27: =G6+G13+G20 | H27: =H6+H13+H20
A28: All segments: paying accounts at year end | B28: =B7+B14+B21 | C28: =C7+C14+C21 | D28: =D7+D14+D21 | E28: =E7+E14+E21 | F28: =F7+F14+F21 | G28: =G7+G14+G21 | H28: =H7+H14+H21
A29: All segments: average paying accounts | B29: =B8+B15+B22 | C29: =C8+C15+C22 | D29: =D8+D15+D22 | E29: =E8+E15+E22 | F29: =F8+F15+F22 | G29: =G8+G15+G22 | H29: =H8+H15+H22
A30: Total revenue | B30: =B10+B17+B24 | C30: =C10+C17+C24 | D30: =D10+D17+D24 | E30: =E10+E17+E24 | F30: =F10+F17+F24 | G30: =G10+G17+G24 | H30: =H10+H17+H24
A31: ARR at year end | B31: =B11+B18+B25 | C31: =C11+C18+C25 | D31: =D11+D18+D25 | E31: =E11+E18+E25 | F31: =F11+F18+F25 | G31: =G11+G18+G25 | H31: =H11+H18+H25
A32: Blended revenue per account = ARR / accounts ($K) | B32: =IF(B28=0,0,B31/B28) | C32: =IF(C28=0,0,C31/C28) | D32: =IF(D28=0,0,D31/D28) | E32: =IF(E28=0,0,E31/E28) | F32: =IF(F28=0,0,F31/F28) | G32: =IF(G28=0,0,G31/G28) | H32: =IF(H28=0,0,H31/H28)
A33: Platform-fee revenue (shippers and importers) | B33: =(B8+B15)*Assumptions!$B$35*Assumptions!$E$46 | C33: =(C8+C15)*Assumptions!$C$35*Assumptions!$E$46 | D33: =(D8+D15)*Assumptions!$D$35*Assumptions!$E$46 | E33: =(E8+E15)*Assumptions!$E$35*Assumptions!$E$46 | F33: =(F8+F15)*Assumptions!$F$35*Assumptions!$E$46 | G33: =(G8+G15)*Assumptions!$G$35*Assumptions!$E$46 | H33: =(H8+H15)*Assumptions!$H$35*Assumptions!$E$46
A34: Recovery-share revenue | B34: =B30-B33 | C34: =C30-C33 | D34: =D30-D33 | E34: =E30-E33 | F34: =F30-F33 | G34: =G30-G33 | H34: =H30-H33
A35: Total recovered for customers | B35: =(B15*Assumptions!$B$36+B8*Assumptions!$B$36*Assumptions!$B$40+B22*Assumptions!$B$41)*Assumptions!$E$46 | C35: =(C15*Assumptions!$C$36+C8*Assumptions!$C$36*Assumptions!$B$40+C22*Assumptions!$C$41)*Assumptions!$E$46 | D35: =(D15*Assumptions!$D$36+D8*Assumptions!$D$36*Assumptions!$B$40+D22*Assumptions!$D$41)*Assumptions!$E$46 | E35: =(E15*Assumptions!$E$36+E8*Assumptions!$E$36*Assumptions!$B$40+E22*Assumptions!$E$41)*Assumptions!$E$46 | F35: =(F15*Assumptions!$F$36+F8*Assumptions!$F$36*Assumptions!$B$40+F22*Assumptions!$F$41)*Assumptions!$E$46 | G35: =(G15*Assumptions!$G$36+G8*Assumptions!$G$36*Assumptions!$B$40+G22*Assumptions!$G$41)*Assumptions!$E$46 | H35: =(H15*Assumptions!$H$36+H8*Assumptions!$H$36*Assumptions!$B$40+H22*Assumptions!$H$41)*Assumptions!$E$46
A36: Net revenue retention = sum over segments of (start accounts - lost) x revenue per account / start ARR | B36: ="" | C36: =IF(B31=0,"",((B7-C6)*C9+(B14-C13)*C16+(B21-C20)*C23)/B31) | D36: =IF(C31=0,"",((C7-D6)*D9+(C14-D13)*D16+(C21-D20)*D23)/C31) | E36: =IF(D31=0,"",((D7-E6)*E9+(D14-E13)*E16+(D21-E20)*E23)/D31) | F36: =IF(E31=0,"",((E7-F6)*F9+(E14-F13)*F16+(E21-F20)*F23)/E31) | G36: =IF(F31=0,"",((F7-G6)*G9+(F14-G13)*G16+(F21-G20)*G23)/F31) | H36: =IF(G31=0,"",((G7-H6)*H9+(G14-H13)*H16+(G21-H20)*H23)/G31)
A37: Revenue growth | B37: ="" | C37: =IF(B30=0,"",C30/B30-1) | D37: =IF(C30=0,"",D30/C30-1) | E37: =IF(D30=0,"",E30/D30-1) | F37: =IF(E30=0,"",F30/E30-1) | G37: =IF(F30=0,"",G30/F30-1) | H37: =IF(G30=0,"",H30/G30-1)
A38: Month ARR crosses the Series A milestone (linear within year) | B38: =IF(B31>=Assumptions!$B$19,12*Assumptions!$B$19/B31,"") | C38: =IF(AND(C31>=Assumptions!$B$19,B31<Assumptions!$B$19),12*(Assumptions!$C$6-1)+12*(Assumptions!$B$19-B31)/(C31-B31),"") | D38: =IF(AND(D31>=Assumptions!$B$19,C31<Assumptions!$B$19),12*(Assumptions!$D$6-1)+12*(Assumptions!$B$19-C31)/(D31-C31),"") | E38: =IF(AND(E31>=Assumptions!$B$19,D31<Assumptions!$B$19),12*(Assumptions!$E$6-1)+12*(Assumptions!$B$19-D31)/(E31-D31),"") | F38: =IF(AND(F31>=Assumptions!$B$19,E31<Assumptions!$B$19),12*(Assumptions!$F$6-1)+12*(Assumptions!$B$19-E31)/(F31-E31),"") | G38: =IF(AND(G31>=Assumptions!$B$19,F31<Assumptions!$B$19),12*(Assumptions!$G$6-1)+12*(Assumptions!$B$19-F31)/(G31-F31),"") | H38: =IF(AND(H31>=Assumptions!$B$19,G31<Assumptions!$B$19),12*(Assumptions!$H$6-1)+12*(Assumptions!$B$19-G31)/(H31-G31),"")
A39: Series A milestone month | B39: =IF(COUNT(B38:H38)=0,"not reached",ROUNDUP(SUM(B38:H38),0))
A40: Year-7 shipper + importer accounts as share of SAM accounts | B40: =IFERROR((H7+H14)/Assumptions!$B$31,"")
...

Sheet Headcount
A1: Headcount and people cost (active scenario)
A2: Headcount = ROUND(plan x scale), founder unscaled, held at prior year from the freeze year. Year-1 FTE-years use the hiring quarter; later years average start and end headcount. Cost = FTE-years x loaded cost x (1 + inflation)^(year - 1).
A3: $K unless stated | B3: ="Y"&Assumptions!$B$6 | C3: ="Y"&Assumptions!$C$6 | D3: ="Y"&Assumptions!$D$6 | E3: ="Y"&Assumptions!$E$6 | F3: ="Y"&Assumptions!$F$6 | G3: ="Y"&Assumptions!$G$6 | H3: ="Y"&Assumptions!$H$6
A4: People at year end
A5: Founder / CEO [G&A] | B5: =Assumptions!$B$61 | C5: =IF(AND(Assumptions!$E$48>0,Assumptions!$C$6>=Assumptions!$E$48,Assumptions!$C$6<Assumptions!$E$48+Assumptions!$E$49),B5,Assumptions!$C$61) | D5: =IF(AND(Assumptions!$E$48>0,Assumptions!$D$6>=Assumptions!$E$48,Assumptions!$D$6<Assumptions!$E$48+Assumptions!$E$49),C5,Assumptions!$D$61) | E5: =IF(AND(Assumptions!$E$48>0,Assumptions!$E$6>=Assumptions!$E$48,Assumptions!$E$6<Assumptions!$E$48+Assumptions!$E$49),D5,Assumptions!$E$61) | F5: =IF(AND(Assumptions!$E$48>0,Assumptions!$F$6>=Assumptions!$E$48,Assumptions!$F$6<Assumptions!$E$48+Assumptions!$E$49),E5,Assumptions!$F$61) | G5: =IF(AND(Assumptions!$E$48>0,Assumptions!$G$6>=Assumptions!$E$48,Assumptions!$G$6<Assumptions!$E$48+Assumptions!$E$49),F5,Assumptions!$G$61) | H5: =IF(AND(Assumptions!$E$48>0,Assumptions!$H$6>=Assumptions!$E$48,Assumptions!$H$6<Assumptions!$E$48+Assumptions!$E$49),G5,Assumptions!$H$61)
A6: Software engineers [Engineering] | B6: =ROUND(Assumptions!$B$65*Assumptions!$E$47,0) | C6: =IF(AND(Assumptions!$E$48>0,Assumptions!$C$6>=Assumptions!$E$48,Assumptions!$C$6<Assumptions!$E$48+Assumptions!$E$49),B6,ROUND(Assumptions!$C$65*Assumptions!$E$47,0)) | D6: =IF(AND(Assumptions!$E$48>0,Assumptions!$D$6>=Assumptions!$E$48,Assumptions!$D$6<Assumptions!$E$48+Assumptions!$E$49),C6,ROUND(Assumptions!$D$65*Assumptions!$E$47,0)) | E6: =IF(AND(Assumptions!$E$48>0,Assumptions!$E$6>=Assumptions!$E$48,Assumptions!$E$6<Assumptions!$E$48+Assumptions!$E$49),D6,ROUND(Assumptions!$E$65*Assumptions!$E$47,0)) | F6: =IF(AND(Assumptions!$E$48>0,Assumptions!$F$6>=Assumptions!$E$48,Assumptions!$F$6<Assumptions!$E$48+Assumptions!$E$49),E6,ROUND(Assumptions!$F$65*Assumptions!$E$47,0)) | G6: =IF(AND(Assumptions!$E$48>0,Assumptions!$G$6>=Assumptions!$E$48,Assumptions!$G$6<Assumptions!$E$48+Assumptions!$E$49),F6,ROUND(Assumptions!$G$65*Assumptions!$E$47,0)) | H6: =IF(AND(Assumptions!$E$48>0,Assumptions!$H$6>=Assumptions!$E$48,Assumptions!$H$6<Assumptions!$E$48+Assumptions!$E$49),G6,ROUND(Assumptions!$H$65*Assumptions!$E$47,0))
A7: ML / data engineers [Engineering] | B7: =ROUND(Assumptions!$B$69*Assumptions!$E$47,0) | C7: =IF(AND(Assumptions!$E$48>0,Assumptions!$C$6>=Assumptions!$E$48,Assumptions!$C$6<Assumptions!$E$48+Assumptions!$E$49),B7,ROUND(Assumptions!$C$69*Assumptions!$E$47,0)) | D7: =IF(AND(Assumptions!$E$48>0,Assumptions!$D$6>=Assumptions!$E$48,Assumptions!$D$6<Assumptions!$E$48+Assumptions!$E$49),C7,ROUND(Assumptions!$D$69*Assumptions!$E$47,0)) | E7: =IF(AND(Assumptions!$E$48>0,Assumptions!$E$6>=Assumptions!$E$48,Assumptions!$E$6<Assumptions!$E$48+Assumptions!$E$49),D7,ROUND(Assumptions!$E$69*Assumptions!$E$47,0)) | F7: =IF(AND(Assumptions!$E$48>0,Assumptions!$F$6>=Assumptions!$E$48,Assumptions!$F$6<Assumptions!$E$48+Assumptions!$E$49),E7,ROUND(Assumptions!$F$69*Assumptions!$E$47,0)) | G7: =IF(AND(Assumptions!$E$48>0,Assumptions!$G$6>=Assumptions!$E$48,Assumptions!$G$6<Assumptions!$E$48+Assumptions!$E$49),F7,ROUND(Assumptions!$G$69*Assumptions!$E$47,0)) | H7: =IF(AND(Assumptions!$E$48>0,Assumptions!$H$6>=Assumptions!$E$48,Assumptions!$H$6<Assumptions!$E$48+Assumptions!$E$49),G7,ROUND(Assumptions!$H$69*Assumptions!$E$47,0))
A8: Security engineer [Security] | B8: =ROUND(Assumptions!$B$73*Assumptions!$E$47,0) | C8: =IF(AND(Assumptions!$E$48>0,Assumptions!$C$6>=Assumptions!$E$48,Assumptions!$C$6<Assumptions!$E$48+Assumptions!$E$49),B8,ROUND(Assumptions!$C$73*Assumptions!$E$47,0)) | D8: =IF(AND(Assumptions!$E$48>0,Assumptions!$D$6>=Assumptions!$E$48,Assumptions!$D$6<Assumptions!$E$48+Assumptions!$E$49),C8,ROUND(Assumptions!$D$73*Assumptions!$E$47,0)) | E8: =IF(AND(Assumptions!$E$48>0,Assumptions!$E$6>=Assumptions!$E$48,Assumptions!$E$6<Assumptions!$E$48+Assumptions!$E$49),D8,ROUND(Assumptions!$E$73*Assumptions!$E$47,0)) | F8: =IF(AND(Assumptions!$E$48>0,Assumptions!$F$6>=Assumptions!$E$48,Assumptions!$F$6<Assumptions!$E$48+Assumptions!$E$49),E8,ROUND(Assumptions!$F$73*Assumptions!$E$47,0)) | G8: =IF(AND(Assumptions!$E$48>0,Assumptions!$G$6>=Assumptions!$E$48,Assumptions!$G$6<Assumptions!$E$48+Assumptions!$E$49),F8,ROUND(Assumptions!$G$73*Assumptions!$E$47,0)) | H8: =IF(AND(Assumptions!$E$48>0,Assumptions!$H$6>=Assumptions!$E$48,Assumptions!$H$6<Assumptions!$E$48+Assumptions!$E$49),G8,ROUND(Assumptions!$H$73*Assumptions!$E$47,0))
A9: Account executives (US) [Sales] | B9: =ROUND(Assumptions!$B$77*Assumptions!$E$47,0) | C9: =IF(AND(Assumptions!$E$48>0,Assumptions!$C$6>=Assumptions!$E$48,Assumptions!$C$6<Assumptions!$E$48+Assumptions!$E$49),B9,ROUND(Assumptions!$C$77*Assumptions!$E$47,0)) | D9: =IF(AND(Assumptions!$E$48>0,Assumptions!$D$6>=Assumptions!$E$48,Assumptions!$D$6<Assumptions!$E$48+Assumptions!$E$49),C9,ROUND(Assumptions!$D$77*Assumptions!$E$47,0)) | E9: =IF(AND(Assumptions!$E$48>0,Assumptions!$E$6>=Assumptions!$E$48,Assumptions!$E$6<Assumptions!$E$48+Assumptions!$E$49),D9,ROUND(Assumptions!$E$77*Assumptions!$E$47,0)) | F9: =IF(AND(Assumptions!$E$48>0,Assumptions!$F$6>=Assumptions!$E$48,Assumptions!$F$6<Assumptions!$E$48+Assumptions!$E$49),E9,ROUND(Assumptions!$F$77*Assumptions!$E$47,0)) | G9: =IF(AND(Assumptions!$E$48>0,Assumptions!$G$6>=Assumptions!$E$48,Assumptions!$G$6<Assumptions!$E$48+Assumptions!$E$49),F9,ROUND(Assumptions!$G$77*Assumptions!$E$47,0)) | H9: =IF(AND(Assumptions!$E$48>0,Assumptions!$H$6>=Assumptions!$E$48,Assumptions!$H$6<Assumptions!$E$48+Assumptions!$E$49),G9,ROUND(Assumptions!$H$77*Assumptions!$E$47,0))
A10: Sales engineer (US) [Sales] | B10: =ROUND(Assumptions!$B$81*Assumptions!$E$47,0) | C10: =IF(AND(Assumptions!$E$48>0,Assumptions!$C$6>=Assumptions!$E$48,Assumptions!$C$6<Assumptions!$E$48+Assumptions!$E$49),B10,ROUND(Assumptions!$C$81*Assumptions!$E$47,0)) | D10: =IF(AND(Assumptions!$E$48>0,Assumptions!$D$6>=Assumptions!$E$48,Assumptions!$D$6<Assumptions!$E$48+Assumptions!$E$49),C10,ROUND(Assumptions!$D$81*Assumptions!$E$47,0)) | E10: =IF(AND(Assumptions!$E$48>0,Assumptions!$E$6>=Assumptions!$E$48,Assumptions!$E$6<Assumptions!$E$48+Assumptions!$E$49),D10,ROUND(Assumptions!$E$81*Assumptions!$E$47,0)) | F10: =IF(AND(Assumptions!$E$48>0,Assumptions!$F$6>=Assumptions!$E$48,Assumptions!$F$6<Assumptions!$E$48+Assumptions!$E$49),E10,ROUND(Assumptions!$F$81*Assumptions!$E$47,0)) | G10: =IF(AND(Assumptions!$E$48>0,Assumptions!$G$6>=Assumptions!$E$48,Assumptions!$G$6<Assumptions!$E$48+Assumptions!$E$49),F10,ROUND(Assumptions!$G$81*Assumptions!$E$47,0)) | H10: =IF(AND(Assumptions!$E$48>0,Assumptions!$H$6>=Assumptions!$E$48,Assumptions!$H$6<Assumptions!$E$48+Assumptions!$E$49),G10,ROUND(Assumptions!$H$81*Assumptions!$E$47,0))
A11: Claims analysts / customer success (US) [Claims operations (COGS)] | B11: =ROUND(Assumptions!$B$85*Assumptions!$E$47,0) | C11: =IF(AND(Assumptions!$E$48>0,Assumptions!$C$6>=Assumptions!$E$48,Assumptions!$C$6<Assumptions!$E$48+Assumptions!$E$49),B11,ROUND(Assumptions!$C$85*Assumptions!$E$47,0)) | D11: =IF(AND(Assumptions!$E$48>0,Assumptions!$D$6>=Assumptions!$E$48,Assumptions!$D$6<Assumptions!$E$48+Assumptions!$E$49),C11,ROUND(Assumptions!$D$85*Assumptions!$E$47,0)) | E11: =IF(AND(Assumptions!$E$48>0,Assumptions!$E$6>=Assumptions!$E$48,Assumptions!$E$6<Assumptions!$E$48+Assumptions!$E$49),D11,ROUND(Assumptions!$E$85*Assumptions!$E$47,0)) | F11: =IF(AND(Assumptions!$E$48>0,Assumptions!$F$6>=Assumptions!$E$48,Assumptions!$F$6<Assumptions!$E$48+Assumptions!$E$49),E11,ROUND(Assumptions!$F$85*Assumptions!$E$47,0)) | G11: =IF(AND(Assumptions!$E$48>0,Assumptions!$G$6>=Assumptions!$E$48,Assumptions!$G$6<Assumptions!$E$48+Assumptions!$E$49),F11,ROUND(Assumptions!$G$85*Assumptions!$E$47,0)) | H11: =IF(AND(Assumptions!$E$48>0,Assumptions!$H$6>=Assumptions!$E$48,Assumptions!$H$6<Assumptions!$E$48+Assumptions!$E$49),G11,ROUND(Assumptions!$H$85*Assumptions!$E$47,0))
A12: Marketing (US) [Marketing] | B12: =ROUND(Assumptions!$B$89*Assumptions!$E$47,0) | C12: =IF(AND(Assumptions!$E$48>0,Assumptions!$C$6>=Assumptions!$E$48,Assumptions!$C$6<Assumptions!$E$48+Assumptions!$E$49),B12,ROUND(Assumptions!$C$89*Assumptions!$E$47,0)) | D12: =IF(AND(Assumptions!$E$48>0,Assumptions!$D$6>=Assumptions!$E$48,Assumptions!$D$6<Assumptions!$E$48+Assumptions!$E$49),C12,ROUND(Assumptions!$D$89*Assumptions!$E$47,0)) | E12: =IF(AND(Assumptions!$E$48>0,Assumptions!$E$6>=Assumptions!$E$48,Assumptions!$E$6<Assumptions!$E$48+Assumptions!$E$49),D12,ROUND(Assumptions!$E$89*Assumptions!$E$47,0)) | F12: =IF(AND(Assumptions!$E$48>0,Assumptions!$F$6>=Assumptions!$E$48,Assumptions!$F$6<Assumptions!$E$48+Assumptions!$E$49),E12,ROUND(Assumptions!$F$89*Assumptions!$E$47,0)) | G12: =IF(AND(Assumptions!$E$48>0,Assumptions!$G$6>=Assumptions!$E$48,Assumptions!$G$6<Assumptions!$E$48+Assumptions!$E$49),F12,ROUND(Assumptions!$G$89*Assumptions!$E$47,0)) | H12: =IF(AND(Assumptions!$E$48>0,Assumptions!$H$6>=Assumptions!$E$48,Assumptions!$H$6<Assumptions!$E$48+Assumptions!$E$49),G12,ROUND(Assumptions!$H$89*Assumptions!$E$47,0))
A13: Finance, legal operations, people [G&A] | B13: =ROUND(Assumptions!$B$93*Assumptions!$E$47,0) | C13: =IF(AND(Assumptions!$E$48>0,Assumptions!$C$6>=Assumptions!$E$48,Assumptions!$C$6<Assumptions!$E$48+Assumptions!$E$49),B13,ROUND(Assumptions!$C$93*Assumptions!$E$47,0)) | D13: =IF(AND(Assumptions!$E$48>0,Assumptions!$D$6>=Assumptions!$E$48,Assumptions!$D$6<Assumptions!$E$48+Assumptions!$E$49),C13,ROUND(Assumptions!$D$93*Assumptions!$E$47,0)) | E13: =IF(AND(Assumptions!$E$48>0,Assumptions!$E$6>=Assumptions!$E$48,Assumptions!$E$6<Assumptions!$E$48+Assumptions!$E$49),D13,ROUND(Assumptions!$E$93*Assumptions!$E$47,0)) | F13: =IF(AND(Assumptions!$E$48>0,Assumptions!$F$6>=Assumptions!$E$48,Assumptions!$F$6<Assumptions!$E$48+Assumptions!$E$49),E13,ROUND(Assumptions!$F$93*Assumptions!$E$47,0)) | G13: =IF(AND(Assumptions!$E$48>0,Assumptions!$G$6>=Assumptions!$E$48,Assumptions!$G$6<Assumptions!$E$48+Assumptions!$E$49),F13,ROUND(Assumptions!$G$93*Assumptions!$E$47,0)) | H13: =IF(AND(Assumptions!$E$48>0,Assumptions!$H$6>=Assumptions!$E$48,Assumptions!$H$6<Assumptions!$E$48+Assumptions!$E$49),G13,ROUND(Assumptions!$H$93*Assumptions!$E$47,0))
A14: Total headcount at year end | B14: =SUM(B5:B13) | C14: =SUM(C5:C13) | D14: =SUM(D5:D13) | E14: =SUM(E5:E13) | F14: =SUM(F5:F13) | G14: =SUM(G5:G13) | H14: =SUM(H5:H13)
A15: Net new hires | B15: =B14 | C15: =MAX(0,C14-B14) | D15: =MAX(0,D14-C14) | E15: =MAX(0,E14-D14) | F15: =MAX(0,F14-E14) | G15: =MAX(0,G14-F14) | H15: =MAX(0,H14-G14)
A16: FTE-years paid in the year
A17: Founder / CEO | B17: =B5*(5-Assumptions!$B$63)/4 | C17: =(B5+C5)/2 | D17: =(C5+D5)/2 | E17: =(D5+E5)/2 | F17: =(E5+F5)/2 | G17: =(F5+G5)/2 | H17: =(G5+H5)/2
A18: Software engineers | B18: =B6*(5-Assumptions!$B$67)/4 | C18: =(B6+C6)/2 | D18: =(C6+D6)/2 | E18: =(D6+E6)/2 | F18: =(E6+F6)/2 | G18: =(F6+G6)/2 | H18: =(G6+H6)/2
A19: ML / data engineers | B19: =B7*(5-Assumptions!$B$71)/4 | C19: =(B7+C7)/2 | D19: =(C7+D7)/2 | E19: =(D7+E7)/2 | F19: =(E7+F7)/2 | G19: =(F7+G7)/2 | H19: =(G7+H7)/2
A20: Security engineer | B20: =B8*(5-Assumptions!$B$75)/4 | C20: =(B8+C8)/2 | D20: =(C8+D8)/2 | E20: =(D8+E8)/2 | F20: =(E8+F8)/2 | G20: =(F8+G8)/2 | H20: =(G8+H8)/2
A21: Account executives (US) | B21: =B9*(5-Assumptions!$B$79)/4 | C21: =(B9+C9)/2 | D21: =(C9+D9)/2 | E21: =(D9+E9)/2 | F21: =(E9+F9)/2 | G21: =(F9+G9)/2 | H21: =(G9+H9)/2
A22: Sales engineer (US) | B22: =B10*(5-Assumptions!$B$83)/4 | C22: =(B10+C10)/2 | D22: =(C10+D10)/2 | E22: =(D10+E10)/2 | F22: =(E10+F10)/2 | G22: =(F10+G10)/2 | H22: =(G10+H10)/2
A23: Claims analysts / customer success (US) | B23: =B11*(5-Assumptions!$B$87)/4 | C23: =(B11+C11)/2 | D23: =(C11+D11)/2 | E23: =(D11+E11)/2 | F23: =(E11+F11)/2 | G23: =(F11+G11)/2 | H23: =(G11+H11)/2
A24: Marketing (US) | B24: =B12*(5-Assumptions!$B$91)/4 | C24: =(B12+C12)/2 | D24: =(C12+D12)/2 | E24: =(D12+E12)/2 | F24: =(E12+F12)/2 | G24: =(F12+G12)/2 | H24: =(G12+H12)/2
A25: Finance, legal operations, people | B25: =B13*(5-Assumptions!$B$95)/4 | C25: =(B13+C13)/2 | D25: =(C13+D13)/2 | E25: =(D13+E13)/2 | F25: =(E13+F13)/2 | G25: =(F13+G13)/2 | H25: =(G13+H13)/2
A26: People cost ($K)
A27: Founder / CEO | B27: =B17*Assumptions!$B$64*(1+Assumptions!$B$8)^(Assumptions!$B$6-1) | C27: =C17*Assumptions!$B$64*(1+Assumptions!$B$8)^(Assumptions!$C$6-1) | D27: =D17*Assumptions!$B$64*(1+Assumptions!$B$8)^(Assumptions!$D$6-1) | E27: =E17*Assumptions!$B$64*(1+Assumptions!$B$8)^(Assumptions!$E$6-1) | F27: =F17*Assumptions!$B$64*(1+Assumptions!$B$8)^(Assumptions!$F$6-1) | G27: =G17*Assumptions!$B$64*(1+Assumptions!$B$8)^(Assumptions!$G$6-1) | H27: =H17*Assumptions!$B$64*(1+Assumptions!$B$8)^(Assumptions!$H$6-1)
A28: Software engineers | B28: =B18*Assumptions!$B$68*(1+Assumptions!$B$8)^(Assumptions!$B$6-1) | C28: =C18*Assumptions!$B$68*(1+Assumptions!$B$8)^(Assumptions!$C$6-1) | D28: =D18*Assumptions!$B$68*(1+Assumptions!$B$8)^(Assumptions!$D$6-1) | E28: =E18*Assumptions!$B$68*(1+Assumptions!$B$8)^(Assumptions!$E$6-1) | F28: =F18*Assumptions!$B$68*(1+Assumptions!$B$8)^(Assumptions!$F$6-1) | G28: =G18*Assumptions!$B$68*(1+Assumptions!$B$8)^(Assumptions!$G$6-1) | H28: =H18*Assumptions!$B$68*(1+Assumptions!$B$8)^(Assumptions!$H$6-1)
A29: ML / data engineers | B29: =B19*Assumptions!$B$72*(1+Assumptions!$B$8)^(Assumptions!$B$6-1) | C29: =C19*Assumptions!$B$72*(1+Assumptions!$B$8)^(Assumptions!$C$6-1) | D29: =D19*Assumptions!$B$72*(1+Assumptions!$B$8)^(Assumptions!$D$6-1) | E29: =E19*Assumptions!$B$72*(1+Assumptions!$B$8)^(Assumptions!$E$6-1) | F29: =F19*Assumptions!$B$72*(1+Assumptions!$B$8)^(Assumptions!$F$6-1) | G29: =G19*Assumptions!$B$72*(1+Assumptions!$B$8)^(Assumptions!$G$6-1) | H29: =H19*Assumptions!$B$72*(1+Assumptions!$B$8)^(Assumptions!$H$6-1)
A30: Security engineer | B30: =B20*Assumptions!$B$76*(1+Assumptions!$B$8)^(Assumptions!$B$6-1) | C30: =C20*Assumptions!$B$76*(1+Assumptions!$B$8)^(Assumptions!$C$6-1) | D30: =D20*Assumptions!$B$76*(1+Assumptions!$B$8)^(Assumptions!$D$6-1) | E30: =E20*Assumptions!$B$76*(1+Assumptions!$B$8)^(Assumptions!$E$6-1) | F30: =F20*Assumptions!$B$76*(1+Assumptions!$B$8)^(Assumptions!$F$6-1) | G30: =G20*Assumptions!$B$76*(1+Assumptions!$B$8)^(Assumptions!$G$6-1) | H30: =H20*Assumptions!$B$76*(1+Assumptions!$B$8)^(Assumptions!$H$6-1)
A31: Account executives (US) | B31: =B21*Assumptions!$B$80*(1+Assumptions!$B$8)^(Assumptions!$B$6-1) | C31: =C21*Assumptions!$B$80*(1+Assumptions!$B$8)^(Assumptions!$C$6-1) | D31: =D21*Assumptions!$B$80*(1+Assumptions!$B$8)^(Assumptions!$D$6-1) | E31: =E21*Assumptions!$B$80*(1+Assumptions!$B$8)^(Assumptions!$E$6-1) | F31: =F21*Assumptions!$B$80*(1+Assumptions!$B$8)^(Assumptions!$F$6-1) | G31: =G21*Assumptions!$B$80*(1+Assumptions!$B$8)^(Assumptions!$G$6-1) | H31: =H21*Assumptions!$B$80*(1+Assumptions!$B$8)^(Assumptions!$H$6-1)
A32: Sales engineer (US) | B32: =B22*Assumptions!$B$84*(1+Assumptions!$B$8)^(Assumptions!$B$6-1) | C32: =C22*Assumptions!$B$84*(1+Assumptions!$B$8)^(Assumptions!$C$6-1) | D32: =D22*Assumptions!$B$84*(1+Assumptions!$B$8)^(Assumptions!$D$6-1) | E32: =E22*Assumptions!$B$84*(1+Assumptions!$B$8)^(Assumptions!$E$6-1) | F32: =F22*Assumptions!$B$84*(1+Assumptions!$B$8)^(Assumptions!$F$6-1) | G32: =G22*Assumptions!$B$84*(1+Assumptions!$B$8)^(Assumptions!$G$6-1) | H32: =H22*Assumptions!$B$84*(1+Assumptions!$B$8)^(Assumptions!$H$6-1)
A33: Claims analysts / customer success (US) | B33: =B23*Assumptions!$B$88*(1+Assumptions!$B$8)^(Assumptions!$B$6-1) | C33: =C23*Assumptions!$B$88*(1+Assumptions!$B$8)^(Assumptions!$C$6-1) | D33: =D23*Assumptions!$B$88*(1+Assumptions!$B$8)^(Assumptions!$D$6-1) | E33: =E23*Assumptions!$B$88*(1+Assumptions!$B$8)^(Assumptions!$E$6-1) | F33: =F23*Assumptions!$B$88*(1+Assumptions!$B$8)^(Assumptions!$F$6-1) | G33: =G23*Assumptions!$B$88*(1+Assumptions!$B$8)^(Assumptions!$G$6-1) | H33: =H23*Assumptions!$B$88*(1+Assumptions!$B$8)^(Assumptions!$H$6-1)
A34: Marketing (US) | B34: =B24*Assumptions!$B$92*(1+Assumptions!$B$8)^(Assumptions!$B$6-1) | C34: =C24*Assumptions!$B$92*(1+Assumptions!$B$8)^(Assumptions!$C$6-1) | D34: =D24*Assumptions!$B$92*(1+Assumptions!$B$8)^(Assumptions!$D$6-1) | E34: =E24*Assumptions!$B$92*(1+Assumptions!$B$8)^(Assumptions!$E$6-1) | F34: =F24*Assumptions!$B$92*(1+Assumptions!$B$8)^(Assumptions!$F$6-1) | G34: =G24*Assumptions!$B$92*(1+Assumptions!$B$8)^(Assumptions!$G$6-1) | H34: =H24*Assumptions!$B$92*(1+Assumptions!$B$8)^(Assumptions!$H$6-1)
A35: Finance, legal operations, people | B35: =B25*Assumptions!$B$96*(1+Assumptions!$B$8)^(Assumptions!$B$6-1) | C35: =C25*Assumptions!$B$96*(1+Assumptions!$B$8)^(Assumptions!$C$6-1) | D35: =D25*Assumptions!$B$96*(1+Assumptions!$B$8)^(Assumptions!$D$6-1) | E35: =E25*Assumptions!$B$96*(1+Assumptions!$B$8)^(Assumptions!$E$6-1) | F35: =F25*Assumptions!$B$96*(1+Assumptions!$B$8)^(Assumptions!$F$6-1) | G35: =G25*Assumptions!$B$96*(1+Assumptions!$B$8)^(Assumptions!$G$6-1) | H35: =H25*Assumptions!$B$96*(1+Assumptions!$B$8)^(Assumptions!$H$6-1)
A36: Total people cost | B36: =SUM(B27:B35) | C36: =SUM(C27:C35) | D36: =SUM(D27:D35) | E36: =SUM(E27:E35) | F36: =SUM(F27:F35) | G36: =SUM(G27:G35) | H36: =SUM(H27:H35)
A37: People cost by department ($K)
A38: Engineering | B38: =B28+B29 | C38: =C28+C29 | D38: =D28+D29 | E38: =E28+E29 | F38: =F28+F29 | G38: =G28+G29 | H38: =H28+H29
A39: Security | B39: =B30 | C39: =C30 | D39: =D30 | E39: =E30 | F39: =F30 | G39: =G30 | H39: =H30
A40: Sales | B40: =B31+B32 | C40: =C31+C32 | D40: =D31+D32 | E40: =E31+E32 | F40: =F31+F32 | G40: =G31+G32 | H40: =H31+H32
...

Sheet OpEx
A1: Operating costs (active scenario)
A2: Other costs = base plan (year 1) and base plan x scale (year 2 on), held at prior year from the freeze year. Departments combine people cost and programme spend.
A3: $K unless stated | B3: ="Y"&Assumptions!$B$6 | C3: ="Y"&Assumptions!$C$6 | D3: ="Y"&Assumptions!$D$6 | E3: ="Y"&Assumptions!$E$6 | F3: ="Y"&Assumptions!$F$6 | G3: ="Y"&Assumptions!$G$6 | H3: ="Y"&Assumptions!$H$6
A4: Other operating costs ($K)
A5: Cloud hosting, data feeds and tooling [COGS] | B5: =Assumptions!$B$98 | C5: =IF(AND(Assumptions!$E$48>0,Assumptions!$C$6>=Assumptions!$E$48,Assumptions!$C$6<Assumptions!$E$48+Assumptions!$E$49),B5,Assumptions!$C$98*Assumptions!$E$47) | D5: =IF(AND(Assumptions!$E$48>0,Assumptions!$D$6>=Assumptions!$E$48,Assumptions!$D$6<Assumptions!$E$48+Assumptions!$E$49),C5,Assumptions!$D$98*Assumptions!$E$47) | E5: =IF(AND(Assumptions!$E$48>0,Assumptions!$E$6>=Assumptions!$E$48,Assumptions!$E$6<Assumptions!$E$48+Assumptions!$E$49),D5,Assumptions!$E$98*Assumptions!$E$47) | F5: =IF(AND(Assumptions!$E$48>0,Assumptions!$F$6>=Assumptions!$E$48,Assumptions!$F$6<Assumptions!$E$48+Assumptions!$E$49),E5,Assumptions!$F$98*Assumptions!$E$47) | G5: =IF(AND(Assumptions!$E$48>0,Assumptions!$G$6>=Assumptions!$E$48,Assumptions!$G$6<Assumptions!$E$48+Assumptions!$E$49),F5,Assumptions!$G$98*Assumptions!$E$47) | H5: =IF(AND(Assumptions!$E$48>0,Assumptions!$H$6>=Assumptions!$E$48,Assumptions!$H$6<Assumptions!$E$48+Assumptions!$E$49),G5,Assumptions!$H$98*Assumptions!$E$47)
A6: Security programme (SOC 2, pen tests, tooling, insurance) [Security] | B6: =Assumptions!$B$99 | C6: =IF(AND(Assumptions!$E$48>0,Assumptions!$C$6>=Assumptions!$E$48,Assumptions!$C$6<Assumptions!$E$48+Assumptions!$E$49),B6,Assumptions!$C$99*Assumptions!$E$47) | D6: =IF(AND(Assumptions!$E$48>0,Assumptions!$D$6>=Assumptions!$E$48,Assumptions!$D$6<Assumptions!$E$48+Assumptions!$E$49),C6,Assumptions!$D$99*Assumptions!$E$47) | E6: =IF(AND(Assumptions!$E$48>0,Assumptions!$E$6>=Assumptions!$E$48,Assumptions!$E$6<Assumptions!$E$48+Assumptions!$E$49),D6,Assumptions!$E$99*Assumptions!$E$47) | F6: =IF(AND(Assumptions!$E$48>0,Assumptions!$F$6>=Assumptions!$E$48,Assumptions!$F$6<Assumptions!$E$48+Assumptions!$E$49),E6,Assumptions!$F$99*Assumptions!$E$47) | G6: =IF(AND(Assumptions!$E$48>0,Assumptions!$G$6>=Assumptions!$E$48,Assumptions!$G$6<Assumptions!$E$48+Assumptions!$E$49),F6,Assumptions!$G$99*Assumptions!$E$47) | H6: =IF(AND(Assumptions!$E$48>0,Assumptions!$H$6>=Assumptions!$E$48,Assumptions!$H$6<Assumptions!$E$48+Assumptions!$E$49),G6,Assumptions!$H$99*Assumptions!$E$47)
A7: Legal and regulatory [G&A] | B7: =Assumptions!$B$100 | C7: =IF(AND(Assumptions!$E$48>0,Assumptions!$C$6>=Assumptions!$E$48,Assumptions!$C$6<Assumptions!$E$48+Assumptions!$E$49),B7,Assumptions!$C$100*Assumptions!$E$47) | D7: =IF(AND(Assumptions!$E$48>0,Assumptions!$D$6>=Assumptions!$E$48,Assumptions!$D$6<Assumptions!$E$48+Assumptions!$E$49),C7,Assumptions!$D$100*Assumptions!$E$47) | E7: =IF(AND(Assumptions!$E$48>0,Assumptions!$E$6>=Assumptions!$E$48,Assumptions!$E$6<Assumptions!$E$48+Assumptions!$E$49),D7,Assumptions!$E$100*Assumptions!$E$47) | F7: =IF(AND(Assumptions!$E$48>0,Assumptions!$F$6>=Assumptions!$E$48,Assumptions!$F$6<Assumptions!$E$48+Assumptions!$E$49),E7,Assumptions!$F$100*Assumptions!$E$47) | G7: =IF(AND(Assumptions!$E$48>0,Assumptions!$G$6>=Assumptions!$E$48,Assumptions!$G$6<Assumptions!$E$48+Assumptions!$E$49),F7,Assumptions!$G$100*Assumptions!$E$47) | H7: =IF(AND(Assumptions!$E$48>0,Assumptions!$H$6>=Assumptions!$E$48,Assumptions!$H$6<Assumptions!$E$48+Assumptions!$E$49),G7,Assumptions!$H$100*Assumptions!$E$47)
A8: Marketing programmes and events [Marketing] | B8: =Assumptions!$B$101 | C8: =IF(AND(Assumptions!$E$48>0,Assumptions!$C$6>=Assumptions!$E$48,Assumptions!$C$6<Assumptions!$E$48+Assumptions!$E$49),B8,Assumptions!$C$101*Assumptions!$E$47) | D8: =IF(AND(Assumptions!$E$48>0,Assumptions!$D$6>=Assumptions!$E$48,Assumptions!$D$6<Assumptions!$E$48+Assumptions!$E$49),C8,Assumptions!$D$101*Assumptions!$E$47) | E8: =IF(AND(Assumptions!$E$48>0,Assumptions!$E$6>=Assumptions!$E$48,Assumptions!$E$6<Assumptions!$E$48+Assumptions!$E$49),D8,Assumptions!$E$101*Assumptions!$E$47) | F8: =IF(AND(Assumptions!$E$48>0,Assumptions!$F$6>=Assumptions!$E$48,Assumptions!$F$6<Assumptions!$E$48+Assumptions!$E$49),E8,Assumptions!$F$101*Assumptions!$E$47) | G8: =IF(AND(Assumptions!$E$48>0,Assumptions!$G$6>=Assumptions!$E$48,Assumptions!$G$6<Assumptions!$E$48+Assumptions!$E$49),F8,Assumptions!$G$101*Assumptions!$E$47) | H8: =IF(AND(Assumptions!$E$48>0,Assumptions!$H$6>=Assumptions!$E$48,Assumptions!$H$6<Assumptions!$E$48+Assumptions!$E$49),G8,Assumptions!$H$101*Assumptions!$E$47)
A9: Travel and customer visits [Sales] | B9: =Assumptions!$B$102 | C9: =IF(AND(Assumptions!$E$48>0,Assumptions!$C$6>=Assumptions!$E$48,Assumptions!$C$6<Assumptions!$E$48+Assumptions!$E$49),B9,Assumptions!$C$102*Assumptions!$E$47) | D9: =IF(AND(Assumptions!$E$48>0,Assumptions!$D$6>=Assumptions!$E$48,Assumptions!$D$6<Assumptions!$E$48+Assumptions!$E$49),C9,Assumptions!$D$102*Assumptions!$E$47) | E9: =IF(AND(Assumptions!$E$48>0,Assumptions!$E$6>=Assumptions!$E$48,Assumptions!$E$6<Assumptions!$E$48+Assumptions!$E$49),D9,Assumptions!$E$102*Assumptions!$E$47) | F9: =IF(AND(Assumptions!$E$48>0,Assumptions!$F$6>=Assumptions!$E$48,Assumptions!$F$6<Assumptions!$E$48+Assumptions!$E$49),E9,Assumptions!$F$102*Assumptions!$E$47) | G9: =IF(AND(Assumptions!$E$48>0,Assumptions!$G$6>=Assumptions!$E$48,Assumptions!$G$6<Assumptions!$E$48+Assumptions!$E$49),F9,Assumptions!$G$102*Assumptions!$E$47) | H9: =IF(AND(Assumptions!$E$48>0,Assumptions!$H$6>=Assumptions!$E$48,Assumptions!$H$6<Assumptions!$E$48+Assumptions!$E$49),G9,Assumptions!$H$102*Assumptions!$E$47)
A10: Office, software, admin, accounting [G&A] | B10: =Assumptions!$B$103 | C10: =IF(AND(Assumptions!$E$48>0,Assumptions!$C$6>=Assumptions!$E$48,Assumptions!$C$6<Assumptions!$E$48+Assumptions!$E$49),B10,Assumptions!$C$103*Assumptions!$E$47) | D10: =IF(AND(Assumptions!$E$48>0,Assumptions!$D$6>=Assumptions!$E$48,Assumptions!$D$6<Assumptions!$E$48+Assumptions!$E$49),C10,Assumptions!$D$103*Assumptions!$E$47) | E10: =IF(AND(Assumptions!$E$48>0,Assumptions!$E$6>=Assumptions!$E$48,Assumptions!$E$6<Assumptions!$E$48+Assumptions!$E$49),D10,Assumptions!$E$103*Assumptions!$E$47) | F10: =IF(AND(Assumptions!$E$48>0,Assumptions!$F$6>=Assumptions!$E$48,Assumptions!$F$6<Assumptions!$E$48+Assumptions!$E$49),E10,Assumptions!$F$103*Assumptions!$E$47) | G10: =IF(AND(Assumptions!$E$48>0,Assumptions!$G$6>=Assumptions!$E$48,Assumptions!$G$6<Assumptions!$E$48+Assumptions!$E$49),F10,Assumptions!$G$103*Assumptions!$E$47) | H10: =IF(AND(Assumptions!$E$48>0,Assumptions!$H$6>=Assumptions!$E$48,Assumptions!$H$6<Assumptions!$E$48+Assumptions!$E$49),G10,Assumptions!$H$103*Assumptions!$E$47)
A11: Partner commission on carrier revenue [Sales] | B11: =Revenue!B24*Assumptions!$B$43 | C11: =Revenue!C24*Assumptions!$B$43 | D11: =Revenue!D24*Assumptions!$B$43 | E11: =Revenue!E24*Assumptions!$B$43 | F11: =Revenue!F24*Assumptions!$B$43 | G11: =Revenue!G24*Assumptions!$B$43 | H11: =Revenue!H24*Assumptions!$B$43
A12: Operating expense by department, excluding cost of revenue ($K)
A13: Engineering | B13: =Headcount!B38 | C13: =Headcount!C38 | D13: =Headcount!D38 | E13: =Headcount!E38 | F13: =Headcount!F38 | G13: =Headcount!G38 | H13: =Headcount!H38
A14: Security | B14: =Headcount!B39+B6 | C14: =Headcount!C39+C6 | D14: =Headcount!D39+D6 | E14: =Headcount!E39+E6 | F14: =Headcount!F39+F6 | G14: =Headcount!G39+G6 | H14: =Headcount!H39+H6
A15: Sales | B15: =Headcount!B40+B9+B11 | C15: =Headcount!C40+C9+C11 | D15: =Headcount!D40+D9+D11 | E15: =Headcount!E40+E9+E11 | F15: =Headcount!F40+F9+F11 | G15: =Headcount!G40+G9+G11 | H15: =Headcount!H40+H9+H11
A16: Marketing | B16: =Headcount!B41+B8 | C16: =Headcount!C41+C8 | D16: =Headcount!D41+D8 | E16: =Headcount!E41+E8 | F16: =Headcount!F41+F8 | G16: =Headcount!G41+G8 | H16: =Headcount!H41+H8
A17: G&A | B17: =Headcount!B42+B7+B10 | C17: =Headcount!C42+C7+C10 | D17: =Headcount!D42+D7+D10 | E17: =Headcount!E42+E7+E10 | F17: =Headcount!F42+F7+F10 | G17: =Headcount!G42+G7+G10 | H17: =Headcount!H42+H7+H10
A18: Total operating expense | B18: =SUM(B13:B17) | C18: =SUM(C13:C17) | D18: =SUM(D13:D17) | E18: =SUM(E13:E17) | F18: =SUM(F13:F17) | G18: =SUM(G13:G17) | H18: =SUM(H13:H17)
A19: Sales and marketing (Sales + Marketing departments) | B19: =B15+B16 | C19: =C15+C16 | D19: =D15+D16 | E19: =E15+E16 | F19: =F15+F16 | G19: =G15+G16 | H19: =H15+H16
A20: Cost of revenue ($K)
A21: Claims operations people | B21: =Headcount!B43 | C21: =Headcount!C43 | D21: =Headcount!D43 | E21: =Headcount!E43 | F21: =Headcount!F43 | G21: =Headcount!G43 | H21: =Headcount!H43
A22: Hosting, data feeds and tooling | B22: =B5 | C22: =C5 | D22: =D5 | E22: =E5 | F22: =F5 | G22: =G5 | H22: =H5
A23: Variable cost = revenue x variable cost % | B23: =Revenue!B30*Assumptions!$E$50 | C23: =Revenue!C30*Assumptions!$E$50 | D23: =Revenue!D30*Assumptions!$E$50 | E23: =Revenue!E30*Assumptions!$E$50 | F23: =Revenue!F30*Assumptions!$E$50 | G23: =Revenue!G30*Assumptions!$E$50 | H23: =Revenue!H30*Assumptions!$E$50
A24: Total cost of revenue | B24: =B21+B22+B23 | C24: =C21+C22+C23 | D24: =D21+D22+D23 | E24: =E21+E22+E23 | F24: =F21+F22+F23 | G24: =G21+G22+G23 | H24: =H21+H22+H23
A26: Year-1 budget by department and quarter ($K). People cost starts in the hiring quarter; non-people costs are spread evenly. | B26: Q1 | C26: Q2 | D26: Q3 | E26: Q4 | F26: Year 1
A27: Founder / CEO [G&A] | B27: =Headcount!B5*IF(1>=Assumptions!$B$63,1,0)*Assumptions!$B$64/4 | C27: =Headcount!B5*IF(2>=Assumptions!$B$63,1,0)*Assumptions!$B$64/4 | D27: =Headcount!B5*IF(3>=Assumptions!$B$63,1,0)*Assumptions!$B$64/4 | E27: =Headcount!B5*IF(4>=Assumptions!$B$63,1,0)*Assumptions!$B$64/4 | F27: =SUM(B27:E27)
A28: Software engineers [Engineering] | B28: =Headcount!B6*IF(1>=Assumptions!$B$67,1,0)*Assumptions!$B$68/4 | C28: =Headcount!B6*IF(2>=Assumptions!$B$67,1,0)*Assumptions!$B$68/4 | D28: =Headcount!B6*IF(3>=Assumptions!$B$67,1,0)*Assumptions!$B$68/4 | E28: =Headcount!B6*IF(4>=Assumptions!$B$67,1,0)*Assumptions!$B$68/4 | F28: =SUM(B28:E28)
A29: ML / data engineers [Engineering] | B29: =Headcount!B7*IF(1>=Assumptions!$B$71,1,0)*Assumptions!$B$72/4 | C29: =Headcount!B7*IF(2>=Assumptions!$B$71,1,0)*Assumptions!$B$72/4 | D29: =Headcount!B7*IF(3>=Assumptions!$B$71,1,0)*Assumptions!$B$72/4 | E29: =Headcount!B7*IF(4>=Assumptions!$B$71,1,0)*Assumptions!$B$72/4 | F29: =SUM(B29:E29)
A30: Security engineer [Security] | B30: =Headcount!B8*IF(1>=Assumptions!$B$75,1,0)*Assumptions!$B$76/4 | C30: =Headcount!B8*IF(2>=Assumptions!$B$75,1,0)*Assumptions!$B$76/4 | D30: =Headcount!B8*IF(3>=Assumptions!$B$75,1,0)*Assumptions!$B$76/4 | E30: =Headcount!B8*IF(4>=Assumptions!$B$75,1,0)*Assumptions!$B$76/4 | F30: =SUM(B30:E30)
A31: Account executives (US) [Sales] | B31: =Headcount!B9*IF(1>=Assumptions!$B$79,1,0)*Assumptions!$B$80/4 | C31: =Headcount!B9*IF(2>=Assumptions!$B$79,1,0)*Assumptions!$B$80/4 | D31: =Headcount!B9*IF(3>=Assumptions!$B$79,1,0)*Assumptions!$B$80/4 | E31: =Headcount!B9*IF(4>=Assumptions!$B$79,1,0)*Assumptions!$B$80/4 | F31: =SUM(B31:E31)
A32: Sales engineer (US) [Sales] | B32: =Headcount!B10*IF(1>=Assumptions!$B$83,1,0)*Assumptions!$B$84/4 | C32: =Headcount!B10*IF(2>=Assumptions!$B$83,1,0)*Assumptions!$B$84/4 | D32: =Headcount!B10*IF(3>=Assumptions!$B$83,1,0)*Assumptions!$B$84/4 | E32: =Headcount!B10*IF(4>=Assumptions!$B$83,1,0)*Assumptions!$B$84/4 | F32: =SUM(B32:E32)
A33: Claims analysts / customer success (US) [Claims operations (COGS)] | B33: =Headcount!B11*IF(1>=Assumptions!$B$87,1,0)*Assumptions!$B$88/4 | C33: =Headcount!B11*IF(2>=Assumptions!$B$87,1,0)*Assumptions!$B$88/4 | D33: =Headcount!B11*IF(3>=Assumptions!$B$87,1,0)*Assumptions!$B$88/4 | E33: =Headcount!B11*IF(4>=Assumptions!$B$87,1,0)*Assumptions!$B$88/4 | F33: =SUM(B33:E33)
A34: Marketing (US) [Marketing] | B34: =Headcount!B12*IF(1>=Assumptions!$B$91,1,0)*Assumptions!$B$92/4 | C34: =Headcount!B12*IF(2>=Assumptions!$B$91,1,0)*Assumptions!$B$92/4 | D34: =Headcount!B12*IF(3>=Assumptions!$B$91,1,0)*Assumptions!$B$92/4 | E34: =Headcount!B12*IF(4>=Assumptions!$B$91,1,0)*Assumptions!$B$92/4 | F34: =SUM(B34:E34)
A35: Finance, legal operations, people [G&A] | B35: =Headcount!B13*IF(1>=Assumptions!$B$95,1,0)*Assumptions!$B$96/4 | C35: =Headcount!B13*IF(2>=Assumptions!$B$95,1,0)*Assumptions!$B$96/4 | D35: =Headcount!B13*IF(3>=Assumptions!$B$95,1,0)*Assumptions!$B$96/4 | E35: =Headcount!B13*IF(4>=Assumptions!$B$95,1,0)*Assumptions!$B$96/4 | F35: =SUM(B35:E35)
A36: Cloud hosting, data feeds and tooling [COGS] | B36: =B5/4 | C36: =B5/4 | D36: =B5/4 | E36: =B5/4 | F36: =SUM(B36:E36)
A37: Security programme (SOC 2, pen tests, tooling, insurance) [Security] | B37: =B6/4 | C37: =B6/4 | D37: =B6/4 | E37: =B6/4 | F37: =SUM(B37:E37)
A38: Legal and regulatory [G&A] | B38: =B7/4 | C38: =B7/4 | D38: =B7/4 | E38: =B7/4 | F38: =SUM(B38:E38)
A39: Marketing programmes and events [Marketing] | B39: =B8/4 | C39: =B8/4 | D39: =B8/4 | E39: =B8/4 | F39: =SUM(B39:E39)
A40: Travel and customer visits [Sales] | B40: =B9/4 | C40: =B9/4 | D40: =B9/4 | E40: =B9/4 | F40: =SUM(B40:E40)
A41: Office, software, admin, accounting [G&A] | B41: =B10/4 | C41: =B10/4 | D41: =B10/4 | E41: =B10/4 | F41: =SUM(B41:E41)
...

Sheet P&L
A1: Income statement (active scenario)
A2: Cost of revenue is built bottom-up (claims staff, hosting and data, variable cost); gross margin is an output.
A3: $K unless stated | B3: ="Y"&Assumptions!$B$6 | C3: ="Y"&Assumptions!$C$6 | D3: ="Y"&Assumptions!$D$6 | E3: ="Y"&Assumptions!$E$6 | F3: ="Y"&Assumptions!$F$6 | G3: ="Y"&Assumptions!$G$6 | H3: ="Y"&Assumptions!$H$6
A4: Revenue | B4: =Revenue!B30 | C4: =Revenue!C30 | D4: =Revenue!D30 | E4: =Revenue!E30 | F4: =Revenue!F30 | G4: =Revenue!G30 | H4: =Revenue!H30
A5: Cost of revenue | B5: =OpEx!B24 | C5: =OpEx!C24 | D5: =OpEx!D24 | E5: =OpEx!E24 | F5: =OpEx!F24 | G5: =OpEx!G24 | H5: =OpEx!H24
A6: Gross profit | B6: =B4-B5 | C6: =C4-C5 | D6: =D4-D5 | E6: =E4-E5 | F6: =F4-F5 | G6: =G4-G5 | H6: =H4-H5
A7: Gross margin | B7: =IF(B4=0,0,B6/B4) | C7: =IF(C4=0,0,C6/C4) | D7: =IF(D4=0,0,D6/D4) | E7: =IF(E4=0,0,E6/E4) | F7: =IF(F4=0,0,F6/F4) | G7: =IF(G4=0,0,G6/G4) | H7: =IF(H4=0,0,H6/H4)
A8: Operating expense: Engineering | B8: =OpEx!B13 | C8: =OpEx!C13 | D8: =OpEx!D13 | E8: =OpEx!E13 | F8: =OpEx!F13 | G8: =OpEx!G13 | H8: =OpEx!H13
A9: Operating expense: Security | B9: =OpEx!B14 | C9: =OpEx!C14 | D9: =OpEx!D14 | E9: =OpEx!E14 | F9: =OpEx!F14 | G9: =OpEx!G14 | H9: =OpEx!H14
A10: Operating expense: Sales | B10: =OpEx!B15 | C10: =OpEx!C15 | D10: =OpEx!D15 | E10: =OpEx!E15 | F10: =OpEx!F15 | G10: =OpEx!G15 | H10: =OpEx!H15
A11: Operating expense: Marketing | B11: =OpEx!B16 | C11: =OpEx!C16 | D11: =OpEx!D16 | E11: =OpEx!E16 | F11: =OpEx!F16 | G11: =OpEx!G16 | H11: =OpEx!H16
A12: Operating expense: G&A | B12: =OpEx!B17 | C12: =OpEx!C17 | D12: =OpEx!D17 | E12: =OpEx!E17 | F12: =OpEx!F17 | G12: =OpEx!G17 | H12: =OpEx!H17
A13: Total operating expense | B13: =SUM(B8:B12) | C13: =SUM(C8:C12) | D13: =SUM(D8:D12) | E13: =SUM(E8:E12) | F13: =SUM(F8:F12) | G13: =SUM(G8:G12) | H13: =SUM(H8:H12)
A14: EBITDA | B14: =B6-B13 | C14: =C6-C13 | D14: =D6-D13 | E14: =E6-E13 | F14: =F6-F13 | G14: =G6-G13 | H14: =H6-H13
A15: EBITDA margin | B15: =IF(B4=0,0,B14/B4) | C15: =IF(C4=0,0,C14/C4) | D15: =IF(D4=0,0,D14/D4) | E15: =IF(E4=0,0,E14/E4) | F15: =IF(F4=0,0,F14/F4) | G15: =IF(G4=0,0,G14/G4) | H15: =IF(H4=0,0,H14/H4)
A16: Depreciation = capex of the last N years / N (N = depreciation life) | B16: =SUMPRODUCT((Assumptions!$B$6:$H$6<=Assumptions!$B$6)*(Assumptions!$B$6:$H$6>Assumptions!$B$6-Assumptions!$B$16)*Headcount!$B$51:$H$51)/Assumptions!$B$16 | C16: =SUMPRODUCT((Assumptions!$B$6:$H$6<=Assumptions!$C$6)*(Assumptions!$B$6:$H$6>Assumptions!$C$6-Assumptions!$B$16)*Headcount!$B$51:$H$51)/Assumptions!$B$16 | D16: =SUMPRODUCT((Assumptions!$B$6:$H$6<=Assumptions!$D$6)*(Assumptions!$B$6:$H$6>Assumptions!$D$6-Assumptions!$B$16)*Headcount!$B$51:$H$51)/Assumptions!$B$16 | E16: =SUMPRODUCT((Assumptions!$B$6:$H$6<=Assumptions!$E$6)*(Assumptions!$B$6:$H$6>Assumptions!$E$6-Assumptions!$B$16)*Headcount!$B$51:$H$51)/Assumptions!$B$16 | F16: =SUMPRODUCT((Assumptions!$B$6:$H$6<=Assumptions!$F$6)*(Assumptions!$B$6:$H$6>Assumptions!$F$6-Assumptions!$B$16)*Headcount!$B$51:$H$51)/Assumptions!$B$16 | G16: =SUMPRODUCT((Assumptions!$B$6:$H$6<=Assumptions!$G$6)*(Assumptions!$B$6:$H$6>Assumptions!$G$6-Assumptions!$B$16)*Headcount!$B$51:$H$51)/Assumptions!$B$16 | H16: =SUMPRODUCT((Assumptions!$B$6:$H$6<=Assumptions!$H$6)*(Assumptions!$B$6:$H$6>Assumptions!$H$6-Assumptions!$B$16)*Headcount!$B$51:$H$51)/Assumptions!$B$16
A17: Operating profit (EBIT) | B17: =B14-B16 | C17: =C14-C16 | D17: =D14-D16 | E17: =E14-E16 | F17: =F14-F16 | G17: =G14-G16 | H17: =H14-H16
A18: Interest income on prior year-end cash | B18: =Assumptions!$B$18*Assumptions!$B$17 | C18: ='Cash Flow'!B17*Assumptions!$B$17 | D18: ='Cash Flow'!C17*Assumptions!$B$17 | E18: ='Cash Flow'!D17*Assumptions!$B$17 | F18: ='Cash Flow'!E17*Assumptions!$B$17 | G18: ='Cash Flow'!F17*Assumptions!$B$17 | H18: ='Cash Flow'!G17*Assumptions!$B$17
A19: Profit before tax | B19: =B17+B18 | C19: =C17+C18 | D19: =D17+D18 | E19: =E17+E18 | F19: =F17+F18 | G19: =G17+G18 | H19: =H17+H18
A20: Cumulative profit before tax (loss pool when negative) | B20: =B19 | C20: =B20+C19 | D20: =C20+D19 | E20: =D20+E19 | F20: =E20+F19 | G20: =F20+G19 | H20: =G20+H19
A21: Income tax after loss carry-forward = rate x increase in positive cumulative profit | B21: =MAX(0,B20)*Assumptions!$B$12 | C21: =MAX(0,MAX(0,C20)-MAX(0,B20))*Assumptions!$B$12 | D21: =MAX(0,MAX(0,D20)-MAX(0,C20))*Assumptions!$B$12 | E21: =MAX(0,MAX(0,E20)-MAX(0,D20))*Assumptions!$B$12 | F21: =MAX(0,MAX(0,F20)-MAX(0,E20))*Assumptions!$B$12 | G21: =MAX(0,MAX(0,G20)-MAX(0,F20))*Assumptions!$B$12 | H21: =MAX(0,MAX(0,H20)-MAX(0,G20))*Assumptions!$B$12
A22: Net income | B22: =B19-B21 | C22: =C19-C21 | D22: =D19-D21 | E22: =E19-E21 | F22: =F19-F21 | G22: =G19-G21 | H22: =H19-H21

Sheet Cash Flow
A1: Cash flow statement (active scenario)
A2: Indirect method. Financing = seed tranches and Series A in the years set on Assumptions.
A3: $K unless stated | B3: ="Y"&Assumptions!$B$6 | C3: ="Y"&Assumptions!$C$6 | D3: ="Y"&Assumptions!$D$6 | E3: ="Y"&Assumptions!$E$6 | F3: ="Y"&Assumptions!$F$6 | G3: ="Y"&Assumptions!$G$6 | H3: ="Y"&Assumptions!$H$6
A4: Net income | B4: ='P&L'!B22 | C4: ='P&L'!C22 | D4: ='P&L'!D22 | E4: ='P&L'!E22 | F4: ='P&L'!F22 | G4: ='P&L'!G22 | H4: ='P&L'!H22
A5: Add back depreciation | B5: ='P&L'!B16 | C5: ='P&L'!C16 | D5: ='P&L'!D16 | E5: ='P&L'!E16 | F5: ='P&L'!F16 | G5: ='P&L'!G16 | H5: ='P&L'!H16
A6: Less increase in receivables | B6: =-('Balance Sheet'!B5-0) | C6: =-('Balance Sheet'!C5-'Balance Sheet'!B5) | D6: =-('Balance Sheet'!D5-'Balance Sheet'!C5) | E6: =-('Balance Sheet'!E5-'Balance Sheet'!D5) | F6: =-('Balance Sheet'!F5-'Balance Sheet'!E5) | G6: =-('Balance Sheet'!G5-'Balance Sheet'!F5) | H6: =-('Balance Sheet'!H5-'Balance Sheet'!G5)
A7: Add increase in payables | B7: ='Balance Sheet'!B8-0 | C7: ='Balance Sheet'!C8-'Balance Sheet'!B8 | D7: ='Balance Sheet'!D8-'Balance Sheet'!C8 | E7: ='Balance Sheet'!E8-'Balance Sheet'!D8 | F7: ='Balance Sheet'!F8-'Balance Sheet'!E8 | G7: ='Balance Sheet'!G8-'Balance Sheet'!F8 | H7: ='Balance Sheet'!H8-'Balance Sheet'!G8
A8: Cash flow from operations | B8: =SUM(B4:B7) | C8: =SUM(C4:C7) | D8: =SUM(D4:D7) | E8: =SUM(E4:E7) | F8: =SUM(F4:F7) | G8: =SUM(G4:G7) | H8: =SUM(H4:H7)
A9: Capital expenditure (equipment) | B9: =-Headcount!B51 | C9: =-Headcount!C51 | D9: =-Headcount!D51 | E9: =-Headcount!E51 | F9: =-Headcount!F51 | G9: =-Headcount!G51 | H9: =-Headcount!H51
A10: Free cash flow (before financing) | B10: =B8+B9 | C10: =C8+C9 | D10: =D8+D9 | E10: =E8+E9 | F10: =F8+F9 | G10: =G8+G9 | H10: =H8+H9
A11: Seed tranche 1 | B11: =IF(Assumptions!$B$6=Assumptions!$B$22,Assumptions!$B$21,0) | C11: =IF(Assumptions!$C$6=Assumptions!$B$22,Assumptions!$B$21,0) | D11: =IF(Assumptions!$D$6=Assumptions!$B$22,Assumptions!$B$21,0) | E11: =IF(Assumptions!$E$6=Assumptions!$B$22,Assumptions!$B$21,0) | F11: =IF(Assumptions!$F$6=Assumptions!$B$22,Assumptions!$B$21,0) | G11: =IF(Assumptions!$G$6=Assumptions!$B$22,Assumptions!$B$21,0) | H11: =IF(Assumptions!$H$6=Assumptions!$B$22,Assumptions!$B$21,0)
A12: Seed tranche 2 | B12: =IF(Assumptions!$B$6=Assumptions!$B$24,Assumptions!$B$23,0) | C12: =IF(Assumptions!$C$6=Assumptions!$B$24,Assumptions!$B$23,0) | D12: =IF(Assumptions!$D$6=Assumptions!$B$24,Assumptions!$B$23,0) | E12: =IF(Assumptions!$E$6=Assumptions!$B$24,Assumptions!$B$23,0) | F12: =IF(Assumptions!$F$6=Assumptions!$B$24,Assumptions!$B$23,0) | G12: =IF(Assumptions!$G$6=Assumptions!$B$24,Assumptions!$B$23,0) | H12: =IF(Assumptions!$H$6=Assumptions!$B$24,Assumptions!$B$23,0)
A13: Series A | B13: =IF(Assumptions!$B$6=Assumptions!$B$26,Assumptions!$B$25,0) | C13: =IF(Assumptions!$C$6=Assumptions!$B$26,Assumptions!$B$25,0) | D13: =IF(Assumptions!$D$6=Assumptions!$B$26,Assumptions!$B$25,0) | E13: =IF(Assumptions!$E$6=Assumptions!$B$26,Assumptions!$B$25,0) | F13: =IF(Assumptions!$F$6=Assumptions!$B$26,Assumptions!$B$25,0) | G13: =IF(Assumptions!$G$6=Assumptions!$B$26,Assumptions!$B$25,0) | H13: =IF(Assumptions!$H$6=Assumptions!$B$26,Assumptions!$B$25,0)
A14: Cash flow from financing | B14: =SUM(B11:B13) | C14: =SUM(C11:C13) | D14: =SUM(D11:D13) | E14: =SUM(E11:E13) | F14: =SUM(F11:F13) | G14: =SUM(G11:G13) | H14: =SUM(H11:H13)
A15: Net change in cash | B15: =B10+B14 | C15: =C10+C14 | D15: =D10+D14 | E15: =E10+E14 | F15: =F10+F14 | G15: =G10+G14 | H15: =H10+H14
A16: Opening cash | B16: =Assumptions!$B$18 | C16: =B17 | D16: =C17 | E16: =D17 | F16: =E17 | G16: =F17 | H16: =G17
A17: Closing cash | B17: =B16+B15 | C17: =C16+C15 | D17: =D16+D15 | E17: =E16+E15 | F17: =F16+F15 | G17: =G16+G15 | H17: =H16+H15
A18: Average monthly net burn = MAX(0, -free cash flow) / 12 | B18: =MAX(0,-B10)/12 | C18: =MAX(0,-C10)/12 | D18: =MAX(0,-D10)/12 | E18: =MAX(0,-E10)/12 | F18: =MAX(0,-F10)/12 | G18: =MAX(0,-G10)/12 | H18: =MAX(0,-H10)/12
A19: Cumulative free cash flow | B19: =B10 | C19: =B19+C10 | D19: =C19+D10 | E19: =D19+E10 | F19: =E19+F10 | G19: =F19+G10 | H19: =G19+H10
A20: Cumulative free cash flow before the Series A year (0 from that year) | B20: =IF(Assumptions!$B$6<Assumptions!$B$26,B19,0) | C20: =IF(Assumptions!$C$6<Assumptions!$B$26,C19,0) | D20: =IF(Assumptions!$D$6<Assumptions!$B$26,D19,0) | E20: =IF(Assumptions!$E$6<Assumptions!$B$26,E19,0) | F20: =IF(Assumptions!$F$6<Assumptions!$B$26,F19,0) | G20: =IF(Assumptions!$G$6<Assumptions!$B$26,G19,0) | H20: =IF(Assumptions!$H$6<Assumptions!$B$26,H19,0)
